Traceback (most recent call last):
  File "/home/codespace/.local/lib/python3.12/site-packages/jupyter_core/utils/__init__.py", line 154, in wrapped
    asyncio.get_running_loop()
RuntimeError: no running event loop

During handling of the above exception, another exception occurred:

Traceback (most recent call last):
  File "/usr/local/python/3.12.1/lib/python3.12/site-packages/jupyter_cache/executors/utils.py", line 58, in single_nb_execution
    executenb(
  File "/home/codespace/.local/lib/python3.12/site-packages/nbclient/client.py", line 1319, in execute
    return NotebookClient(nb=nb, resources=resources, km=km, **kwargs).execute()
           ^^^^^^^^^^^^^^^^^^^^^^^^^^^^^^^^^^^^^^^^^^^^^^^^^^^^^^^^^^^^^^^^^^^^^
  File "/home/codespace/.local/lib/python3.12/site-packages/jupyter_core/utils/__init__.py", line 158, in wrapped
    return loop.run_until_complete(inner)
           ^^^^^^^^^^^^^^^^^^^^^^^^^^^^^^
  File "/usr/local/python/3.12.1/lib/python3.12/asyncio/base_events.py", line 684, in run_until_complete
    return future.result()
           ^^^^^^^^^^^^^^^
  File "/home/codespace/.local/lib/python3.12/site-packages/nbclient/client.py", line 709, in async_execute
    await self.async_execute_cell(
  File "/home/codespace/.local/lib/python3.12/site-packages/nbclient/client.py", line 1062, in async_execute_cell
    await self._check_raise_for_error(cell, cell_index, exec_reply)
  File "/home/codespace/.local/lib/python3.12/site-packages/nbclient/client.py", line 918, in _check_raise_for_error
    raise CellExecutionError.from_cell_and_msg(cell, exec_reply_content)
nbclient.exceptions.CellExecutionError: An error occurred while executing the following cell:
------------------
# Ubah kolom 'date' menjadi tipe datetime
no2_asli['date'] = pd.to_datetime(no2_asli['date'])
no2_asli.info()

no2 = no2_asli.copy()

# Urutkan data berdasarkan tanggal
no2 = no2.sort_values('date')

# Set kolom 'date' sebagai index
no2 = no2.set_index('date')
print(no2.head(5))
------------------


[31m---------------------------------------------------------------------------[39m
[31mKeyError[39m                                  Traceback (most recent call last)
[36mFile [39m[32m~/.local/lib/python3.12/site-packages/pandas/core/indexes/base.py:3812[39m, in [36mIndex.get_loc[39m[34m(self, key)[39m
[32m   3811[39m [38;5;28;01mtry[39;00m:
[32m-> [39m[32m3812[39m     [38;5;28;01mreturn[39;00m [38;5;28;43mself[39;49m[43m.[49m[43m_engine[49m[43m.[49m[43mget_loc[49m[43m([49m[43mcasted_key[49m[43m)[49m
[32m   3813[39m [38;5;28;01mexcept[39;00m [38;5;167;01mKeyError[39;00m [38;5;28;01mas[39;00m err:

[36mFile [39m[32mpandas/_libs/index.pyx:167[39m, in [36mpandas._libs.index.IndexEngine.get_loc[39m[34m()[39m

[36mFile [39m[32mpandas/_libs/index.pyx:196[39m, in [36mpandas._libs.index.IndexEngine.get_loc[39m[34m()[39m

[36mFile [39m[32mpandas/_libs/hashtable_class_helper.pxi:7088[39m, in [36mpandas._libs.hashtable.PyObjectHashTable.get_item[39m[34m()[39m

[36mFile [39m[32mpandas/_libs/hashtable_class_helper.pxi:7096[39m, in [36mpandas._libs.hashtable.PyObjectHashTable.get_item[39m[34m()[39m

[31mKeyError[39m: 'date'

The above exception was the direct cause of the following exception:

[31mKeyError[39m                                  Traceback (most recent call last)
[36mCell[39m[36m [39m[32mIn[4][39m[32m, line 2[39m
[32m      1[39m [38;5;66;03m# Ubah kolom 'date' menjadi tipe datetime[39;00m
[32m----> [39m[32m2[39m no2_asli[[33m'[39m[33mdate[39m[33m'[39m] = pd.to_datetime([43mno2_asli[49m[43m[[49m[33;43m'[39;49m[33;43mdate[39;49m[33;43m'[39;49m[43m][49m)
[32m      3[39m no2_asli.info()
[32m      5[39m no2 = no2_asli.copy()

[36mFile [39m[32m~/.local/lib/python3.12/site-packages/pandas/core/frame.py:4107[39m, in [36mDataFrame.__getitem__[39m[34m(self, key)[39m
[32m   4105[39m [38;5;28;01mif[39;00m [38;5;28mself[39m.columns.nlevels > [32m1[39m:
[32m   4106[39m     [38;5;28;01mreturn[39;00m [38;5;28mself[39m._getitem_multilevel(key)
[32m-> [39m[32m4107[39m indexer = [38;5;28;43mself[39;49m[43m.[49m[43mcolumns[49m[43m.[49m[43mget_loc[49m[43m([49m[43mkey[49m[43m)[49m
[32m   4108[39m [38;5;28;01mif[39;00m is_integer(indexer):
[32m   4109[39m     indexer = [indexer]

[36mFile [39m[32m~/.local/lib/python3.12/site-packages/pandas/core/indexes/base.py:3819[39m, in [36mIndex.get_loc[39m[34m(self, key)[39m
[32m   3814[39m     [38;5;28;01mif[39;00m [38;5;28misinstance[39m(casted_key, [38;5;28mslice[39m) [38;5;129;01mor[39;00m (
[32m   3815[39m         [38;5;28misinstance[39m(casted_key, abc.Iterable)
[32m   3816[39m         [38;5;129;01mand[39;00m [38;5;28many[39m([38;5;28misinstance[39m(x, [38;5;28mslice[39m) [38;5;28;01mfor[39;00m x [38;5;129;01min[39;00m casted_key)
[32m   3817[39m     ):
[32m   3818[39m         [38;5;28;01mraise[39;00m InvalidIndexError(key)
[32m-> [39m[32m3819[39m     [38;5;28;01mraise[39;00m [38;5;167;01mKeyError[39;00m(key) [38;5;28;01mfrom[39;00m[38;5;250m [39m[34;01merr[39;00m
[32m   3820[39m [38;5;28;01mexcept[39;00m [38;5;167;01mTypeError[39;00m:
[32m   3821[39m     [38;5;66;03m# If we have a listlike key, _check_indexing_error will raise[39;00m
[32m   3822[39m     [38;5;66;03m#  InvalidIndexError. Otherwise we fall through and re-raise[39;00m
[32m   3823[39m     [38;5;66;03m#  the TypeError.[39;00m
[32m   3824[39m     [38;5;28mself[39m._check_indexing_error(key)

[31mKeyError[39m: 'date'

